2024-03-19 09:34:59,377 - INFO - hello_app: Home page requested
2024-03-19 09:35:34,318 - INFO - hello_app: Home page requested
2024-03-19 09:35:48,885 - ERROR - hello_app: Exception on /auth/login [POST]
Traceback (most recent call last):
  File "c:\Users\zimul\Documents\flask2\2\.venv\Lib\site-packages\flask\app.py", line 1463, in wsgi_app
    response = self.full_dispatch_request()
               ^^^^^^^^^^^^^^^^^^^^^^^^^^^^
  File "c:\Users\zimul\Documents\flask2\2\.venv\Lib\site-packages\flask\app.py", line 872, in full_dispatch_request
    rv = self.handle_user_exception(e)
         ^^^^^^^^^^^^^^^^^^^^^^^^^^^^^
  File "c:\Users\zimul\Documents\flask2\2\.venv\Lib\site-packages\flask\app.py", line 870, in full_dispatch_request
    rv = self.dispatch_request()
         ^^^^^^^^^^^^^^^^^^^^^^^
  File "c:\Users\zimul\Documents\flask2\2\.venv\Lib\site-packages\flask\app.py", line 855, in dispatch_request
    return self.ensure_sync(self.view_functions[rule.endpoint])(**view_args)  # type: ignore[no-any-return]
           ^^^^^^^^^^^^^^^^^^^^^^^^^^^^^^^^^^^^^^^^^^^^^^^^^^^^^^^^^^^^^^^^^
  File "C:\Users\zimul\Documents\flask2\2\hello_app\auth.py", line 31, in login
    session['user_id'] = account.id
                         ^^^^^^^^^^
AttributeError: 'Account' object has no attribute 'id'
2024-03-19 09:35:55,575 - ERROR - hello_app: Exception on /auth/login [POST]
Traceback (most recent call last):
  File "c:\Users\zimul\Documents\flask2\2\.venv\Lib\site-packages\flask\app.py", line 1463, in wsgi_app
    response = self.full_dispatch_request()
               ^^^^^^^^^^^^^^^^^^^^^^^^^^^^
  File "c:\Users\zimul\Documents\flask2\2\.venv\Lib\site-packages\flask\app.py", line 872, in full_dispatch_request
    rv = self.handle_user_exception(e)
         ^^^^^^^^^^^^^^^^^^^^^^^^^^^^^
  File "c:\Users\zimul\Documents\flask2\2\.venv\Lib\site-packages\flask\app.py", line 870, in full_dispatch_request
    rv = self.dispatch_request()
         ^^^^^^^^^^^^^^^^^^^^^^^
  File "c:\Users\zimul\Documents\flask2\2\.venv\Lib\site-packages\flask\app.py", line 855, in dispatch_request
    return self.ensure_sync(self.view_functions[rule.endpoint])(**view_args)  # type: ignore[no-any-return]
           ^^^^^^^^^^^^^^^^^^^^^^^^^^^^^^^^^^^^^^^^^^^^^^^^^^^^^^^^^^^^^^^^^
  File "C:\Users\zimul\Documents\flask2\2\hello_app\auth.py", line 31, in login
    session['user_id'] = account.id
                         ^^^^^^^^^^
AttributeError: 'Account' object has no attribute 'id'
2024-03-19 09:38:29,518 - INFO - hello_app: Home page requested
2024-03-19 09:39:08,861 - INFO - hello_app: Home page requested
2024-03-19 09:39:13,437 - INFO - hello_app: Home page requested
2024-03-19 09:39:41,977 - ERROR - hello_app: Exception on /auth/login [POST]
Traceback (most recent call last):
  File "c:\Users\zimul\Documents\flask2\2\.venv\Lib\site-packages\flask\app.py", line 1463, in wsgi_app
    response = self.full_dispatch_request()
               ^^^^^^^^^^^^^^^^^^^^^^^^^^^^
  File "c:\Users\zimul\Documents\flask2\2\.venv\Lib\site-packages\flask\app.py", line 872, in full_dispatch_request
    rv = self.handle_user_exception(e)
         ^^^^^^^^^^^^^^^^^^^^^^^^^^^^^
  File "c:\Users\zimul\Documents\flask2\2\.venv\Lib\site-packages\flask\app.py", line 870, in full_dispatch_request
    rv = self.dispatch_request()
         ^^^^^^^^^^^^^^^^^^^^^^^
  File "c:\Users\zimul\Documents\flask2\2\.venv\Lib\site-packages\flask\app.py", line 855, in dispatch_request
    return self.ensure_sync(self.view_functions[rule.endpoint])(**view_args)  # type: ignore[no-any-return]
           ^^^^^^^^^^^^^^^^^^^^^^^^^^^^^^^^^^^^^^^^^^^^^^^^^^^^^^^^^^^^^^^^^
  File "C:\Users\zimul\Documents\flask2\2\hello_app\auth.py", line 31, in login
    session['user_id'] = account.id
                         ^^^^^^^^^^
AttributeError: 'Account' object has no attribute 'id'
2024-03-19 09:42:35,091 - ERROR - hello_app: Exception on /auth/login [POST]
Traceback (most recent call last):
  File "c:\Users\zimul\Documents\flask2\2\.venv\Lib\site-packages\flask\app.py", line 1463, in wsgi_app
    response = self.full_dispatch_request()
               ^^^^^^^^^^^^^^^^^^^^^^^^^^^^
  File "c:\Users\zimul\Documents\flask2\2\.venv\Lib\site-packages\flask\app.py", line 872, in full_dispatch_request
    rv = self.handle_user_exception(e)
         ^^^^^^^^^^^^^^^^^^^^^^^^^^^^^
  File "c:\Users\zimul\Documents\flask2\2\.venv\Lib\site-packages\flask\app.py", line 870, in full_dispatch_request
    rv = self.dispatch_request()
         ^^^^^^^^^^^^^^^^^^^^^^^
  File "c:\Users\zimul\Documents\flask2\2\.venv\Lib\site-packages\flask\app.py", line 855, in dispatch_request
    return self.ensure_sync(self.view_functions[rule.endpoint])(**view_args)  # type: ignore[no-any-return]
           ^^^^^^^^^^^^^^^^^^^^^^^^^^^^^^^^^^^^^^^^^^^^^^^^^^^^^^^^^^^^^^^^^
  File "C:\Users\zimul\Documents\flask2\2\hello_app\auth.py", line 31, in login
    session['user_id'] = account.accountID
                         ^^^^^^^^^^
AttributeError: 'Account' object has no attribute 'id'
2024-03-19 09:42:41,430 - ERROR - hello_app: Exception on /auth/login [POST]
Traceback (most recent call last):
  File "c:\Users\zimul\Documents\flask2\2\.venv\Lib\site-packages\flask\app.py", line 1463, in wsgi_app
    response = self.full_dispatch_request()
               ^^^^^^^^^^^^^^^^^^^^^^^^^^^^
  File "c:\Users\zimul\Documents\flask2\2\.venv\Lib\site-packages\flask\app.py", line 872, in full_dispatch_request
    rv = self.handle_user_exception(e)
         ^^^^^^^^^^^^^^^^^^^^^^^^^^^^^
  File "c:\Users\zimul\Documents\flask2\2\.venv\Lib\site-packages\flask\app.py", line 870, in full_dispatch_request
    rv = self.dispatch_request()
         ^^^^^^^^^^^^^^^^^^^^^^^
  File "c:\Users\zimul\Documents\flask2\2\.venv\Lib\site-packages\flask\app.py", line 855, in dispatch_request
    return self.ensure_sync(self.view_functions[rule.endpoint])(**view_args)  # type: ignore[no-any-return]
           ^^^^^^^^^^^^^^^^^^^^^^^^^^^^^^^^^^^^^^^^^^^^^^^^^^^^^^^^^^^^^^^^^
  File "C:\Users\zimul\Documents\flask2\2\hello_app\auth.py", line 31, in login
    session['user_id'] = account.accountID
                         ^^^^^^^^^^
AttributeError: 'Account' object has no attribute 'id'
2024-03-19 09:43:16,311 - INFO - hello_app: Home page requested
2024-03-19 09:43:25,997 - ERROR - hello_app: Exception on /auth/login [POST]
Traceback (most recent call last):
  File "c:\Users\zimul\Documents\flask2\2\.venv\Lib\site-packages\flask\app.py", line 1463, in wsgi_app
    response = self.full_dispatch_request()
               ^^^^^^^^^^^^^^^^^^^^^^^^^^^^
  File "c:\Users\zimul\Documents\flask2\2\.venv\Lib\site-packages\flask\app.py", line 872, in full_dispatch_request
    rv = self.handle_user_exception(e)
         ^^^^^^^^^^^^^^^^^^^^^^^^^^^^^
  File "c:\Users\zimul\Documents\flask2\2\.venv\Lib\site-packages\flask\app.py", line 870, in full_dispatch_request
    rv = self.dispatch_request()
         ^^^^^^^^^^^^^^^^^^^^^^^
  File "c:\Users\zimul\Documents\flask2\2\.venv\Lib\site-packages\flask\app.py", line 855, in dispatch_request
    return self.ensure_sync(self.view_functions[rule.endpoint])(**view_args)  # type: ignore[no-any-return]
           ^^^^^^^^^^^^^^^^^^^^^^^^^^^^^^^^^^^^^^^^^^^^^^^^^^^^^^^^^^^^^^^^^
  File "C:\Users\zimul\Documents\flask2\2\hello_app\auth.py", line 32, in login
    session['user_role'] = account.role
                           ^^^^^^^^^^^^
AttributeError: 'Account' object has no attribute 'role'
2024-03-19 10:12:10,934 - INFO - hello_app: Home page requested
2024-03-19 10:12:24,403 - INFO - hello_app: Home page requested
2024-03-19 10:12:44,788 - INFO - hello_app: Home page requested
2024-03-19 10:12:50,702 - INFO - hello_app: Home page requested
2024-03-19 10:13:38,862 - INFO - hello_app: Home page requested
2024-03-19 10:14:03,392 - INFO - hello_app: Home page requested
2024-03-19 10:21:29,005 - INFO - hello_app: Home page requested
2024-03-19 10:21:37,220 - INFO - hello_app: Home page requested
2024-03-19 10:25:41,107 - INFO - hello_app: Home page requested
2024-03-19 10:25:49,508 - INFO - hello_app: Home page requested
2024-03-19 10:30:12,653 - INFO - hello_app: Home page requested
2024-03-19 10:43:40,013 - INFO - hello_app: Home page requested
2024-03-19 10:44:00,933 - INFO - hello_app: Home page requested
2024-03-19 10:44:08,620 - INFO - hello_app: Home page requested
2024-03-19 10:44:17,205 - ERROR - hello_app: Exception on /notes/delete/12 [GET]
Traceback (most recent call last):
  File "c:\Users\zimul\Documents\flask2\2\.venv\Lib\site-packages\flask\app.py", line 1463, in wsgi_app
    response = self.full_dispatch_request()
               ^^^^^^^^^^^^^^^^^^^^^^^^^^^^
  File "c:\Users\zimul\Documents\flask2\2\.venv\Lib\site-packages\flask\app.py", line 872, in full_dispatch_request
    rv = self.handle_user_exception(e)
         ^^^^^^^^^^^^^^^^^^^^^^^^^^^^^
  File "c:\Users\zimul\Documents\flask2\2\.venv\Lib\site-packages\flask\app.py", line 870, in full_dispatch_request
    rv = self.dispatch_request()
         ^^^^^^^^^^^^^^^^^^^^^^^
  File "c:\Users\zimul\Documents\flask2\2\.venv\Lib\site-packages\flask\app.py", line 855, in dispatch_request
    return self.ensure_sync(self.view_functions[rule.endpoint])(**view_args)  # type: ignore[no-any-return]
           ^^^^^^^^^^^^^^^^^^^^^^^^^^^^^^^^^^^^^^^^^^^^^^^^^^^^^^^^^^^^^^^^^
  File "C:\Users\zimul\Documents\flask2\2\hello_app\auth.py", line 16, in decorated_function
    return f(*args, **kwargs)
           ^^^^^^^^^^^^^^^^^^
  File "C:\Users\zimul\Documents\flask2\2\hello_app\notes.py", line 54, in delete_note
    if note.author_id == session.get('user_id') or session.get('role') == 2:
       ^^^^^^^^^^^^^^
AttributeError: 'Note' object has no attribute 'author_id'. Did you mean: 'author'?
2024-03-19 10:45:38,653 - INFO - hello_app: Home page requested
2024-03-19 10:46:09,631 - INFO - hello_app: Home page requested
2024-03-19 10:46:19,696 - INFO - hello_app: Home page requested
2024-03-19 10:46:28,704 - INFO - hello_app: Home page requested
2024-03-19 10:46:39,723 - INFO - hello_app: Home page requested
2024-03-19 10:46:48,940 - INFO - hello_app: Home page requested
2024-03-19 10:47:11,116 - INFO - hello_app: Home page requested
2024-03-19 10:47:31,728 - INFO - hello_app: Home page requested
2024-03-19 10:47:51,540 - INFO - hello_app: Home page requested
2024-03-19 10:48:18,463 - INFO - hello_app: Home page requested
2024-03-19 10:48:27,551 - INFO - hello_app: Home page requested
2024-03-19 10:52:56,498 - INFO - hello_app: Home page requested
2024-03-19 10:53:00,051 - INFO - hello_app: Home page requested
2024-03-19 10:53:08,083 - INFO - hello_app: Home page requested
2024-03-19 10:53:20,229 - INFO - hello_app: Home page requested
2024-03-19 10:53:25,613 - INFO - hello_app: Home page requested
2024-03-19 10:53:29,843 - INFO - hello_app: Home page requested
2024-03-19 10:54:22,268 - INFO - hello_app: Home page requested
2024-03-19 10:54:24,750 - INFO - hello_app: Home page requested
2024-03-19 10:54:36,793 - INFO - hello_app: Home page requested
2024-03-19 10:54:39,963 - INFO - hello_app: Home page requested
2024-03-19 10:54:52,283 - INFO - hello_app: Home page requested
2024-03-19 11:02:24,407 - INFO - hello_app: Home page requested
2024-03-19 11:02:33,120 - INFO - hello_app: Home page requested
2024-03-19 11:02:45,395 - INFO - hello_app: Home page requested
2024-03-19 11:02:52,548 - INFO - hello_app: Home page requested
2024-03-19 11:36:01,906 - INFO - hello_app: Home page requested
2024-03-19 11:36:13,112 - INFO - hello_app: Home page requested
2024-03-19 11:36:32,722 - INFO - hello_app: Home page requested
2024-03-19 11:36:36,703 - INFO - hello_app: Home page requested
2024-03-19 11:36:41,615 - INFO - hello_app: Home page requested
2024-03-19 11:36:45,931 - INFO - hello_app: Home page requested
2024-03-19 12:03:21,816 - INFO - hello_app: Home page requested
2024-03-19 12:03:31,261 - INFO - hello_app: Home page requested
2024-03-19 12:03:48,399 - INFO - hello_app: Home page requested
2024-03-19 12:03:57,726 - INFO - hello_app: Home page requested
2024-03-19 12:41:06,482 - INFO - hello_app: Home page requested from: 127.0.0.1
2024-03-19 12:41:13,821 - ERROR - hello_app: Exception on /auth/login [POST]
Traceback (most recent call last):
  File "c:\Users\zimul\Documents\flask2\2\.venv\Lib\site-packages\flask\app.py", line 1463, in wsgi_app
    response = self.full_dispatch_request()
               ^^^^^^^^^^^^^^^^^^^^^^^^^^^^
  File "c:\Users\zimul\Documents\flask2\2\.venv\Lib\site-packages\flask\app.py", line 872, in full_dispatch_request
    rv = self.handle_user_exception(e)
         ^^^^^^^^^^^^^^^^^^^^^^^^^^^^^
  File "c:\Users\zimul\Documents\flask2\2\.venv\Lib\site-packages\flask\app.py", line 870, in full_dispatch_request
    rv = self.dispatch_request()
         ^^^^^^^^^^^^^^^^^^^^^^^
  File "c:\Users\zimul\Documents\flask2\2\.venv\Lib\site-packages\flask\app.py", line 855, in dispatch_request
    return self.ensure_sync(self.view_functions[rule.endpoint])(**view_args)  # type: ignore[no-any-return]
           ^^^^^^^^^^^^^^^^^^^^^^^^^^^^^^^^^^^^^^^^^^^^^^^^^^^^^^^^^^^^^^^^^
  File "C:\Users\zimul\Documents\flask2\2\hello_app\auth.py", line 38, in login
    flash('Invalid username or password', 'error')
  File "c:\Users\zimul\Documents\flask2\2\.venv\Lib\site-packages\flask\helpers.py", line 323, in flash
    session["_flashes"] = flashes
    ~~~~~~~^^^^^^^^^^^^
  File "c:\Users\zimul\Documents\flask2\2\.venv\Lib\site-packages\flask\sessions.py", line 102, in _fail
    raise RuntimeError(
RuntimeError: The session is unavailable because no secret key was set.  Set the secret_key on the application to something unique and secret.
2024-03-19 12:42:53,296 - INFO - hello_app: Home page requested from: 127.0.0.1
2024-03-19 12:42:59,958 - ERROR - hello_app: Exception on /auth/login [POST]
Traceback (most recent call last):
  File "c:\Users\zimul\Documents\flask2\2\.venv\Lib\site-packages\flask\app.py", line 1463, in wsgi_app
    response = self.full_dispatch_request()
               ^^^^^^^^^^^^^^^^^^^^^^^^^^^^
  File "c:\Users\zimul\Documents\flask2\2\.venv\Lib\site-packages\flask\app.py", line 872, in full_dispatch_request
    rv = self.handle_user_exception(e)
         ^^^^^^^^^^^^^^^^^^^^^^^^^^^^^
  File "c:\Users\zimul\Documents\flask2\2\.venv\Lib\site-packages\flask\app.py", line 870, in full_dispatch_request
    rv = self.dispatch_request()
         ^^^^^^^^^^^^^^^^^^^^^^^
  File "c:\Users\zimul\Documents\flask2\2\.venv\Lib\site-packages\flask\app.py", line 855, in dispatch_request
    return self.ensure_sync(self.view_functions[rule.endpoint])(**view_args)  # type: ignore[no-any-return]
           ^^^^^^^^^^^^^^^^^^^^^^^^^^^^^^^^^^^^^^^^^^^^^^^^^^^^^^^^^^^^^^^^^
  File "C:\Users\zimul\Documents\flask2\2\hello_app\auth.py", line 38, in login
    flash('Invalid username or password', 'error')
  File "c:\Users\zimul\Documents\flask2\2\.venv\Lib\site-packages\flask\helpers.py", line 323, in flash
    session["_flashes"] = flashes
    ~~~~~~~^^^^^^^^^^^^
  File "c:\Users\zimul\Documents\flask2\2\.venv\Lib\site-packages\flask\sessions.py", line 102, in _fail
    raise RuntimeError(
RuntimeError: The session is unavailable because no secret key was set.  Set the secret_key on the application to something unique and secret.
2024-03-19 12:47:34,530 - INFO - hello_app: Home page requested from: 127.0.0.1
2024-03-19 12:47:42,868 - ERROR - hello_app: Exception on /auth/login [POST]
Traceback (most recent call last):
  File "c:\Users\zimul\Documents\flask2\2\.venv\Lib\site-packages\flask\app.py", line 1463, in wsgi_app
    response = self.full_dispatch_request()
               ^^^^^^^^^^^^^^^^^^^^^^^^^^^^
  File "c:\Users\zimul\Documents\flask2\2\.venv\Lib\site-packages\flask\app.py", line 872, in full_dispatch_request
    rv = self.handle_user_exception(e)
         ^^^^^^^^^^^^^^^^^^^^^^^^^^^^^
  File "c:\Users\zimul\Documents\flask2\2\.venv\Lib\site-packages\flask\app.py", line 870, in full_dispatch_request
    rv = self.dispatch_request()
         ^^^^^^^^^^^^^^^^^^^^^^^
  File "c:\Users\zimul\Documents\flask2\2\.venv\Lib\site-packages\flask\app.py", line 855, in dispatch_request
    return self.ensure_sync(self.view_functions[rule.endpoint])(**view_args)  # type: ignore[no-any-return]
           ^^^^^^^^^^^^^^^^^^^^^^^^^^^^^^^^^^^^^^^^^^^^^^^^^^^^^^^^^^^^^^^^^
  File "C:\Users\zimul\Documents\flask2\2\hello_app\auth.py", line 38, in login
    flash('Invalid username or password', 'error')
  File "c:\Users\zimul\Documents\flask2\2\.venv\Lib\site-packages\flask\helpers.py", line 323, in flash
    session["_flashes"] = flashes
    ~~~~~~~^^^^^^^^^^^^
  File "c:\Users\zimul\Documents\flask2\2\.venv\Lib\site-packages\flask\sessions.py", line 102, in _fail
    raise RuntimeError(
RuntimeError: The session is unavailable because no secret key was set.  Set the secret_key on the application to something unique and secret.
2024-03-19 12:50:02,943 - INFO - hello_app: Home page requested from: 127.0.0.1
2024-03-19 12:50:12,612 - ERROR - hello_app: Exception on /auth/login [POST]
Traceback (most recent call last):
  File "c:\Users\zimul\Documents\flask2\2\.venv\Lib\site-packages\flask\app.py", line 1463, in wsgi_app
    response = self.full_dispatch_request()
               ^^^^^^^^^^^^^^^^^^^^^^^^^^^^
  File "c:\Users\zimul\Documents\flask2\2\.venv\Lib\site-packages\flask\app.py", line 872, in full_dispatch_request
    rv = self.handle_user_exception(e)
         ^^^^^^^^^^^^^^^^^^^^^^^^^^^^^
  File "c:\Users\zimul\Documents\flask2\2\.venv\Lib\site-packages\flask\app.py", line 870, in full_dispatch_request
    rv = self.dispatch_request()
         ^^^^^^^^^^^^^^^^^^^^^^^
  File "c:\Users\zimul\Documents\flask2\2\.venv\Lib\site-packages\flask\app.py", line 855, in dispatch_request
    return self.ensure_sync(self.view_functions[rule.endpoint])(**view_args)  # type: ignore[no-any-return]
           ^^^^^^^^^^^^^^^^^^^^^^^^^^^^^^^^^^^^^^^^^^^^^^^^^^^^^^^^^^^^^^^^^
  File "C:\Users\zimul\Documents\flask2\2\hello_app\auth.py", line 36, in login
    flash('Invalid username or password', 'error')
  File "c:\Users\zimul\Documents\flask2\2\.venv\Lib\site-packages\flask\helpers.py", line 323, in flash
    session["_flashes"] = flashes
    ~~~~~~~^^^^^^^^^^^^
  File "c:\Users\zimul\Documents\flask2\2\.venv\Lib\site-packages\flask\sessions.py", line 102, in _fail
    raise RuntimeError(
RuntimeError: The session is unavailable because no secret key was set.  Set the secret_key on the application to something unique and secret.
2024-03-19 12:56:16,499 - INFO - hello_app: Home page requested from: 127.0.0.1
2024-03-19 12:56:24,760 - ERROR - hello_app: Exception on /auth/login [POST]
Traceback (most recent call last):
  File "c:\Users\zimul\Documents\flask2\2\.venv\Lib\site-packages\flask\app.py", line 1463, in wsgi_app
    response = self.full_dispatch_request()
               ^^^^^^^^^^^^^^^^^^^^^^^^^^^^
  File "c:\Users\zimul\Documents\flask2\2\.venv\Lib\site-packages\flask\app.py", line 872, in full_dispatch_request
    rv = self.handle_user_exception(e)
         ^^^^^^^^^^^^^^^^^^^^^^^^^^^^^
  File "c:\Users\zimul\Documents\flask2\2\.venv\Lib\site-packages\flask\app.py", line 870, in full_dispatch_request
    rv = self.dispatch_request()
         ^^^^^^^^^^^^^^^^^^^^^^^
  File "c:\Users\zimul\Documents\flask2\2\.venv\Lib\site-packages\flask\app.py", line 855, in dispatch_request
    return self.ensure_sync(self.view_functions[rule.endpoint])(**view_args)  # type: ignore[no-any-return]
           ^^^^^^^^^^^^^^^^^^^^^^^^^^^^^^^^^^^^^^^^^^^^^^^^^^^^^^^^^^^^^^^^^
  File "C:\Users\zimul\Documents\flask2\2\hello_app\auth.py", line 38, in login
    flash('Invalid username or password', 'error')
  File "c:\Users\zimul\Documents\flask2\2\.venv\Lib\site-packages\flask\helpers.py", line 323, in flash
    session["_flashes"] = flashes
    ~~~~~~~^^^^^^^^^^^^
  File "c:\Users\zimul\Documents\flask2\2\.venv\Lib\site-packages\flask\sessions.py", line 102, in _fail
    raise RuntimeError(
RuntimeError: The session is unavailable because no secret key was set.  Set the secret_key on the application to something unique and secret.
2024-03-19 13:13:41,046 - INFO - hello_app: Home page requested from: 127.0.0.1
2024-03-19 13:13:49,323 - ERROR - hello_app: Exception on /auth/login [POST]
Traceback (most recent call last):
  File "c:\Users\zimul\Documents\flask2\2\.venv\Lib\site-packages\flask\app.py", line 1463, in wsgi_app
    response = self.full_dispatch_request()
               ^^^^^^^^^^^^^^^^^^^^^^^^^^^^
  File "c:\Users\zimul\Documents\flask2\2\.venv\Lib\site-packages\flask\app.py", line 872, in full_dispatch_request
    rv = self.handle_user_exception(e)
         ^^^^^^^^^^^^^^^^^^^^^^^^^^^^^
  File "c:\Users\zimul\Documents\flask2\2\.venv\Lib\site-packages\flask\app.py", line 870, in full_dispatch_request
    rv = self.dispatch_request()
         ^^^^^^^^^^^^^^^^^^^^^^^
  File "c:\Users\zimul\Documents\flask2\2\.venv\Lib\site-packages\flask\app.py", line 855, in dispatch_request
    return self.ensure_sync(self.view_functions[rule.endpoint])(**view_args)  # type: ignore[no-any-return]
           ^^^^^^^^^^^^^^^^^^^^^^^^^^^^^^^^^^^^^^^^^^^^^^^^^^^^^^^^^^^^^^^^^
  File "C:\Users\zimul\Documents\flask2\2\hello_app\auth.py", line 36, in login
    flash('Invalid username or password', 'error')
  File "c:\Users\zimul\Documents\flask2\2\.venv\Lib\site-packages\flask\helpers.py", line 323, in flash
    session["_flashes"] = flashes
    ~~~~~~~^^^^^^^^^^^^
  File "c:\Users\zimul\Documents\flask2\2\.venv\Lib\site-packages\flask\sessions.py", line 102, in _fail
    raise RuntimeError(
RuntimeError: The session is unavailable because no secret key was set.  Set the secret_key on the application to something unique and secret.
2024-03-19 13:19:23,004 - INFO - hello_app: Home page requested from: 127.0.0.1
2024-03-19 13:19:56,822 - INFO - hello_app: Home page requested from: 127.0.0.1
2024-03-19 13:20:16,169 - INFO - hello_app: Home page requested from: 127.0.0.1
2024-03-19 13:20:25,925 - INFO - hello_app: Home page requested from: 127.0.0.1
2024-03-19 13:20:42,166 - INFO - hello_app: Home page requested from: 127.0.0.1
2024-03-19 13:20:49,078 - INFO - hello_app: Home page requested from: 127.0.0.1
2024-03-19 13:21:19,937 - INFO - hello_app: Home page requested from: 127.0.0.1
2024-03-19 13:28:55,586 - INFO - hello_app: Home page requested from: 127.0.0.1
2024-03-19 13:28:57,842 - INFO - hello_app: Home page requested from: 127.0.0.1
2024-03-19 13:29:04,627 - INFO - hello_app: Home page requested from: 127.0.0.1
2024-03-19 13:29:39,828 - INFO - hello_app: Home page requested from: 127.0.0.1
2024-03-19 13:44:41,990 - INFO - hello_app: Home page requested from: 127.0.0.1
2024-03-19 13:45:02,908 - INFO - hello_app: Home page requested from: 127.0.0.1
2024-03-19 13:45:14,390 - INFO - hello_app: Home page requested from: 127.0.0.1
2024-03-19 13:45:23,074 - INFO - hello_app: Home page requested from: 127.0.0.1
2024-03-19 13:45:26,553 - INFO - hello_app: Home page requested from: 127.0.0.1
2024-03-19 13:47:22,714 - INFO - hello_app: Home page requested from: 127.0.0.1
2024-03-19 15:16:17,811 - INFO - hello_app: Home page requested from: 127.0.0.1
2024-03-19 15:16:28,768 - INFO - hello_app: Home page requested from: 127.0.0.1
2024-03-19 15:16:39,510 - INFO - hello_app: Home page requested from: 127.0.0.1
2024-03-19 15:16:43,178 - INFO - hello_app: Home page requested from: 127.0.0.1
2024-03-19 17:49:37,623 - INFO - hello_app: Home page requested from: 127.0.0.1
2024-03-19 17:49:50,859 - INFO - hello_app: Home page requested from: 127.0.0.1
2024-03-19 17:50:28,496 - INFO - hello_app: Home page requested from: 127.0.0.1
2024-03-19 17:50:46,809 - INFO - hello_app: Home page requested from: 127.0.0.1
2024-03-19 17:50:58,378 - INFO - hello_app: Home page requested from: 127.0.0.1
2024-03-19 17:51:13,446 - INFO - hello_app: Home page requested from: 127.0.0.1
2024-03-19 17:51:16,420 - INFO - hello_app: Home page requested from: 127.0.0.1
2024-03-19 17:51:38,019 - INFO - hello_app: Home page requested from: 127.0.0.1
